<?xml version="1.0" ?>
<robot name="URDF" xmlns:xacro="http://www.ros.org/wiki/xacro">

<xacro:include filename="$(find URDF_description)/urdf/materials.xacro" />
<xacro:include filename="$(find URDF_description)/urdf/URDF.trans" />
<xacro:include filename="$(find URDF_description)/urdf/URDF.gazebo" />
<link name="base_link">
  <inertial>
    <origin xyz="6.344469282889335e-07 9.630583816808883e-08 0.009339707950421956" rpy="0 0 0"/>
    <mass value="1.7917000554764084"/>
    <inertia ixx="0.007319" iyy="0.008199" izz="0.006343" ixy="0.0" iyz="-0.0" ixz="0.0"/>
  </inertial>
  <visual>
    <origin xyz="0 0 0" rpy="0 0 0"/>
    <geometry>
      <mesh filename="package://URDF_description/meshes/base_link.stl" scale="0.001 0.001 0.001"/>
    </geometry>
    <material name="silver"/>
  </visual>
  <collision>
    <origin xyz="0 0 0" rpy="0 0 0"/>
    <geometry>
      <mesh filename="package://URDF_description/meshes/base_link.stl" scale="0.001 0.001 0.001"/>
    </geometry>
  </collision>
</link>

<link name="shell_Sp2rR_fork_v6_1">
  <inertial>
    <origin xyz="0.0021019794411417537 -0.06439480964821326 6.206772757977319e-07" rpy="0 0 0"/>
    <mass value="0.7500725921888876"/>
    <inertia ixx="0.002127" iyy="0.001315" izz="0.001773" ixy="3.1e-05" iyz="-0.0" ixz="0.0"/>
  </inertial>
  <visual>
    <origin xyz="0.000626 0.1279 -0.56588" rpy="0 0 0"/>
    <geometry>
      <mesh filename="package://URDF_description/meshes/shell_Sp2rR_fork_v6_1.stl" scale="0.001 0.001 0.001"/>
    </geometry>
    <material name="silver"/>
  </visual>
  <collision>
    <origin xyz="0.000626 0.1279 -0.56588" rpy="0 0 0"/>
    <geometry>
      <mesh filename="package://URDF_description/meshes/shell_Sp2rR_fork_v6_1.stl" scale="0.001 0.001 0.001"/>
    </geometry>
  </collision>
</link>

<link name="shell_Sr2wR_fork_v14_1">
  <inertial>
    <origin xyz="-0.00676747992007232 0.0004767253667617988 -0.06374328238729865" rpy="0 0 0"/>
    <mass value="0.978545587385679"/>
    <inertia ixx="0.00345" iyy="0.004379" izz="0.002679" ixy="-3e-06" iyz="1e-05" ixz="0.000256"/>
  </inertial>
  <visual>
    <origin xyz="-0.000394 0.21629 -0.56588" rpy="0 0 0"/>
    <geometry>
      <mesh filename="package://URDF_description/meshes/shell_Sr2wR_fork_v14_1.stl" scale="0.001 0.001 0.001"/>
    </geometry>
    <material name="silver"/>
  </visual>
  <collision>
    <origin xyz="-0.000394 0.21629 -0.56588" rpy="0 0 0"/>
    <geometry>
      <mesh filename="package://URDF_description/meshes/shell_Sr2wR_fork_v14_1.stl" scale="0.001 0.001 0.001"/>
    </geometry>
  </collision>
</link>

<link name="shell_Humerus_Fork_v8_1">
  <inertial>
    <origin xyz="-0.00349645916677135 0.0026396319475400776 -0.1044043730983521" rpy="0 0 0"/>
    <mass value="0.8766732505471245"/>
    <inertia ixx="0.003702" iyy="0.003977" izz="0.001443" ixy="-2e-06" iyz="6e-05" ixz="1.8e-05"/>
  </inertial>
  <visual>
    <origin xyz="0.000656 0.21629 -0.419397" rpy="0 0 0"/>
    <geometry>
      <mesh filename="package://URDF_description/meshes/shell_Humerus_Fork_v8_1.stl" scale="0.001 0.001 0.001"/>
    </geometry>
    <material name="silver"/>
  </visual>
  <collision>
    <origin xyz="0.000656 0.21629 -0.419397" rpy="0 0 0"/>
    <geometry>
      <mesh filename="package://URDF_description/meshes/shell_Humerus_Fork_v8_1.stl" scale="0.001 0.001 0.001"/>
    </geometry>
  </collision>
</link>

<link name="shell_Ulna_Fork_v5_1">
  <inertial>
    <origin xyz="9.629013296950169e-06 -0.0034444794909641585 -0.045239397147101235" rpy="0 0 0"/>
    <mass value="0.6981589105562731"/>
    <inertia ixx="0.002413" iyy="0.001742" izz="0.001763" ixy="0.0" iyz="9.7e-05" ixz="-0.0"/>
  </inertial>
  <visual>
    <origin xyz="0.000656 0.21552 -0.268007" rpy="0 0 0"/>
    <geometry>
      <mesh filename="package://URDF_description/meshes/shell_Ulna_Fork_v5_1.stl" scale="0.001 0.001 0.001"/>
    </geometry>
    <material name="silver"/>
  </visual>
  <collision>
    <origin xyz="0.000656 0.21552 -0.268007" rpy="0 0 0"/>
    <geometry>
      <mesh filename="package://URDF_description/meshes/shell_Ulna_Fork_v5_1.stl" scale="0.001 0.001 0.001"/>
    </geometry>
  </collision>
</link>

<link name="shell_Radius_gen2_v31_1">
  <inertial>
    <origin xyz="9.37116891963196e-06 -0.0011784535992988288 -0.12499075706160681" rpy="0 0 0"/>
    <mass value="0.8769222512153771"/>
    <inertia ixx="0.003786" iyy="0.003445" izz="0.001483" ixy="0.0" iyz="-3.9e-05" ixz="0.0"/>
  </inertial>
  <visual>
    <origin xyz="0.000656 0.21647 -0.167525" rpy="0 0 0"/>
    <geometry>
      <mesh filename="package://URDF_description/meshes/shell_Radius_gen2_v31_1.stl" scale="0.001 0.001 0.001"/>
    </geometry>
    <material name="silver"/>
  </visual>
  <collision>
    <origin xyz="0.000656 0.21647 -0.167525" rpy="0 0 0"/>
    <geometry>
      <mesh filename="package://URDF_description/meshes/shell_Radius_gen2_v31_1.stl" scale="0.001 0.001 0.001"/>
    </geometry>
  </collision>
</link>

<link name="shell_Sp2rR_fork_v6_Mirror__1">
  <inertial>
    <origin xyz="0.002101979441141694 0.0643948096482127 6.206772759087542e-07" rpy="0 0 0"/>
    <mass value="0.7500725921888887"/>
    <inertia ixx="0.002127" iyy="0.001315" izz="0.001773" ixy="-3.1e-05" iyz="0.0" ixz="0.0"/>
  </inertial>
  <visual>
    <origin xyz="0.000626 -0.1279 -0.56588" rpy="0 0 0"/>
    <geometry>
      <mesh filename="package://URDF_description/meshes/shell_Sp2rR_fork_v6_Mirror__1.stl" scale="0.001 0.001 0.001"/>
    </geometry>
    <material name="silver"/>
  </visual>
  <collision>
    <origin xyz="0.000626 -0.1279 -0.56588" rpy="0 0 0"/>
    <geometry>
      <mesh filename="package://URDF_description/meshes/shell_Sp2rR_fork_v6_Mirror__1.stl" scale="0.001 0.001 0.001"/>
    </geometry>
  </collision>
</link>

<link name="shell_Sr2wR_fork_v14_Mirror__1">
  <inertial>
    <origin xyz="-0.0067674799200723775 -0.000476725366761771 -0.06374328238729887" rpy="0 0 0"/>
    <mass value="0.978545587385679"/>
    <inertia ixx="0.00345" iyy="0.004379" izz="0.002679" ixy="3e-06" iyz="-1e-05" ixz="0.000256"/>
  </inertial>
  <visual>
    <origin xyz="-0.000394 -0.21629 -0.56588" rpy="0 0 0"/>
    <geometry>
      <mesh filename="package://URDF_description/meshes/shell_Sr2wR_fork_v14_Mirror__1.stl" scale="0.001 0.001 0.001"/>
    </geometry>
    <material name="silver"/>
  </visual>
  <collision>
    <origin xyz="-0.000394 -0.21629 -0.56588" rpy="0 0 0"/>
    <geometry>
      <mesh filename="package://URDF_description/meshes/shell_Sr2wR_fork_v14_Mirror__1.stl" scale="0.001 0.001 0.001"/>
    </geometry>
  </collision>
</link>

<link name="shell_Humerus_Fork_v8_Mirror__1">
  <inertial>
    <origin xyz="-0.00349645916677128 -0.00263963194754005 -0.10440437309835243" rpy="0 0 0"/>
    <mass value="0.8766732505471228"/>
    <inertia ixx="0.003702" iyy="0.003977" izz="0.001443" ixy="2e-06" iyz="-6e-05" ixz="1.8e-05"/>
  </inertial>
  <visual>
    <origin xyz="0.000656 -0.21629 -0.419397" rpy="0 0 0"/>
    <geometry>
      <mesh filename="package://URDF_description/meshes/shell_Humerus_Fork_v8_Mirror__1.stl" scale="0.001 0.001 0.001"/>
    </geometry>
    <material name="silver"/>
  </visual>
  <collision>
    <origin xyz="0.000656 -0.21629 -0.419397" rpy="0 0 0"/>
    <geometry>
      <mesh filename="package://URDF_description/meshes/shell_Humerus_Fork_v8_Mirror__1.stl" scale="0.001 0.001 0.001"/>
    </geometry>
  </collision>
</link>

<link name="shell_Ulna_Fork_v5_Mirror__1">
  <inertial>
    <origin xyz="9.629013323651141e-06 0.0034444794909401777 -0.04523939714710584" rpy="0 0 0"/>
    <mass value="0.6981589105558812"/>
    <inertia ixx="0.002413" iyy="0.001742" izz="0.001763" ixy="-0.0" iyz="-9.7e-05" ixz="-0.0"/>
  </inertial>
  <visual>
    <origin xyz="0.000656 -0.21552 -0.268007" rpy="0 0 0"/>
    <geometry>
      <mesh filename="package://URDF_description/meshes/shell_Ulna_Fork_v5_Mirror__1.stl" scale="0.001 0.001 0.001"/>
    </geometry>
    <material name="silver"/>
  </visual>
  <collision>
    <origin xyz="0.000656 -0.21552 -0.268007" rpy="0 0 0"/>
    <geometry>
      <mesh filename="package://URDF_description/meshes/shell_Ulna_Fork_v5_Mirror__1.stl" scale="0.001 0.001 0.001"/>
    </geometry>
  </collision>
</link>

<link name="shell_Radius_gen2_v31_Mirror__1">
  <inertial>
    <origin xyz="9.35442364117709e-06 0.001178586098906531 -0.12399059902227968" rpy="0 0 0"/>
    <mass value="0.8769197049872686"/>
    <inertia ixx="0.003786" iyy="0.003445" izz="0.001483" ixy="-0.0" iyz="3.9e-05" ixz="0.0"/>
  </inertial>
  <visual>
    <origin xyz="0.000656 -0.21647 -0.167525" rpy="0 0 0"/>
    <geometry>
      <mesh filename="package://URDF_description/meshes/shell_Radius_gen2_v31_Mirror__1.stl" scale="0.001 0.001 0.001"/>
    </geometry>
    <material name="silver"/>
  </visual>
  <collision>
    <origin xyz="0.000656 -0.21647 -0.167525" rpy="0 0 0"/>
    <geometry>
      <mesh filename="package://URDF_description/meshes/shell_Radius_gen2_v31_Mirror__1.stl" scale="0.001 0.001 0.001"/>
    </geometry>
  </collision>
</link>

<link name="hand_secondIter_v9_Mirror__1">
  <inertial>
    <origin xyz="-0.00343585355905074 0.005064161716607729 -0.06415791866922996" rpy="0 0 0"/>
    <mass value="0.3405481010141835"/>
    <inertia ixx="0.001299" iyy="0.001101" izz="0.000435" ixy="0.000104" iyz="-4.4e-05" ixz="-9e-06"/>
  </inertial>
  <visual>
    <origin xyz="0.000591 0.21647 0.040262" rpy="0 0 0"/>
    <geometry>
      <mesh filename="package://URDF_description/meshes/hand_secondIter_v9_Mirror__1.stl" scale="0.001 0.001 0.001"/>
    </geometry>
    <material name="silver"/>
  </visual>
  <collision>
    <origin xyz="0.000591 0.21647 0.040262" rpy="0 0 0"/>
    <geometry>
      <mesh filename="package://URDF_description/meshes/hand_secondIter_v9_Mirror__1.stl" scale="0.001 0.001 0.001"/>
    </geometry>
  </collision>
</link>

<link name="hand_secondIter_v9_1">
  <inertial>
    <origin xyz="-0.0034358606226666207 -0.005064161397557804 -0.06415791810231503" rpy="0 0 0"/>
    <mass value="0.3405480032822976"/>
    <inertia ixx="0.001299" iyy="0.001101" izz="0.000435" ixy="-0.000104" iyz="4.4e-05" ixz="-9e-06"/>
  </inertial>
  <visual>
    <origin xyz="0.000591 -0.21647 0.039262" rpy="0 0 0"/>
    <geometry>
      <mesh filename="package://URDF_description/meshes/hand_secondIter_v9_1.stl" scale="0.001 0.001 0.001"/>
    </geometry>
    <material name="silver"/>
  </visual>
  <collision>
    <origin xyz="0.000591 -0.21647 0.039262" rpy="0 0 0"/>
    <geometry>
      <mesh filename="package://URDF_description/meshes/hand_secondIter_v9_1.stl" scale="0.001 0.001 0.001"/>
    </geometry>
  </collision>
</link>

<link name="shell_Fr2w_Fork_v6_1">
  <inertial>
    <origin xyz="-0.01340370877585597 -1.2894743445560791e-07 0.08970880755819671" rpy="0 0 0"/>
    <mass value="1.6442394861044132"/>
    <inertia ixx="0.00625" iyy="0.011252" izz="0.008561" ixy="-0.0" iyz="-0.0" ixz="0.0009"/>
  </inertial>
  <visual>
    <origin xyz="-0.0 -0.0 -0.08448" rpy="0 0 0"/>
    <geometry>
      <mesh filename="package://URDF_description/meshes/shell_Fr2w_Fork_v6_1.stl" scale="0.001 0.001 0.001"/>
    </geometry>
    <material name="silver"/>
  </visual>
  <collision>
    <origin xyz="-0.0 -0.0 -0.08448" rpy="0 0 0"/>
    <geometry>
      <mesh filename="package://URDF_description/meshes/shell_Fr2w_Fork_v6_1.stl" scale="0.001 0.001 0.001"/>
    </geometry>
  </collision>
</link>

<link name="shell_Fp2r_Fork_dual_v3_1">
  <inertial>
    <origin xyz="-0.0009545465799092011 -0.004178761336656475 6.734819535392234e-08" rpy="0 0 0"/>
    <mass value="0.14616316531477574"/>
    <inertia ixx="0.000321" iyy="0.000454" izz="0.000433" ixy="-9e-06" iyz="-0.0" ixz="0.0"/>
  </inertial>
  <visual>
    <origin xyz="-0.0305 -0.0 -0.23668" rpy="0 0 0"/>
    <geometry>
      <mesh filename="package://URDF_description/meshes/shell_Fp2r_Fork_dual_v3_1.stl" scale="0.001 0.001 0.001"/>
    </geometry>
    <material name="silver"/>
  </visual>
  <collision>
    <origin xyz="-0.0305 -0.0 -0.23668" rpy="0 0 0"/>
    <geometry>
      <mesh filename="package://URDF_description/meshes/shell_Fp2r_Fork_dual_v3_1.stl" scale="0.001 0.001 0.001"/>
    </geometry>
  </collision>
</link>

<link name="shell_torso_1">
  <inertial>
    <origin xyz="-0.03195954300461257 5.802064973826098e-07 0.20829691873491818" rpy="0 0 0"/>
    <mass value="5.204862583543319"/>
    <inertia ixx="0.112579" iyy="0.094706" izz="0.056724" ixy="0.0" iyz="0.0" ixz="0.00427"/>
  </inertial>
  <visual>
    <origin xyz="-0.031374 0.0 -0.23668" rpy="0 0 0"/>
    <geometry>
      <mesh filename="package://URDF_description/meshes/shell_torso_1.stl" scale="0.001 0.001 0.001"/>
    </geometry>
    <material name="silver"/>
  </visual>
  <collision>
    <origin xyz="-0.031374 0.0 -0.23668" rpy="0 0 0"/>
    <geometry>
      <mesh filename="package://URDF_description/meshes/shell_torso_1.stl" scale="0.001 0.001 0.001"/>
    </geometry>
  </collision>
</link>

<link name="scaphoid_1">
  <inertial>
    <origin xyz="-1.589994440170158e-07 -1.3481000982196178e-08 4.058087324926296e-07" rpy="0 0 0"/>
    <mass value="0.025917448823465455"/>
    <inertia ixx="4e-06" iyy="4e-06" izz="7e-06" ixy="0.0" iyz="-0.0" ixz="-0.0"/>
  </inertial>
  <visual>
    <origin xyz="0.000591 0.21647 0.040262" rpy="0 0 0"/>
    <geometry>
      <mesh filename="package://URDF_description/meshes/scaphoid_1.stl" scale="0.001 0.001 0.001"/>
    </geometry>
    <material name="silver"/>
  </visual>
  <collision>
    <origin xyz="0.000591 0.21647 0.040262" rpy="0 0 0"/>
    <geometry>
      <mesh filename="package://URDF_description/meshes/scaphoid_1.stl" scale="0.001 0.001 0.001"/>
    </geometry>
  </collision>
</link>

<link name="scaphoid_Mirror__1">
  <inertial>
    <origin xyz="-1.589994440014033e-07 1.3481000954440603e-08 4.05808732402424e-07" rpy="0 0 0"/>
    <mass value="0.025917448823465455"/>
    <inertia ixx="4e-06" iyy="4e-06" izz="7e-06" ixy="-0.0" iyz="0.0" ixz="-0.0"/>
  </inertial>
  <visual>
    <origin xyz="0.000591 -0.21647 0.039262" rpy="0 0 0"/>
    <geometry>
      <mesh filename="package://URDF_description/meshes/scaphoid_Mirror__1.stl" scale="0.001 0.001 0.001"/>
    </geometry>
    <material name="silver"/>
  </visual>
  <collision>
    <origin xyz="0.000591 -0.21647 0.039262" rpy="0 0 0"/>
    <geometry>
      <mesh filename="package://URDF_description/meshes/scaphoid_Mirror__1.stl" scale="0.001 0.001 0.001"/>
    </geometry>
  </collision>
</link>

<link name="shell_Hp2r_Fork_v9_1">
  <inertial>
    <origin xyz="-0.014199618503806523 -0.04853350073814798 3.440536566843701e-05" rpy="0 0 0"/>
    <mass value="0.9668645115659276"/>
    <inertia ixx="0.002752" iyy="0.003388" izz="0.002866" ixy="-3.4e-05" iyz="1e-06" ixz="-0.0"/>
  </inertial>
  <visual>
    <origin xyz="0.0 0.07805 -0.0" rpy="0 0 0"/>
    <geometry>
      <mesh filename="package://URDF_description/meshes/shell_Hp2r_Fork_v9_1.stl" scale="0.001 0.001 0.001"/>
    </geometry>
    <material name="silver"/>
  </visual>
  <collision>
    <origin xyz="0.0 0.07805 -0.0" rpy="0 0 0"/>
    <geometry>
      <mesh filename="package://URDF_description/meshes/shell_Hp2r_Fork_v9_1.stl" scale="0.001 0.001 0.001"/>
    </geometry>
  </collision>
</link>

<link name="shell_Hr2w_Fork_v16_1">
  <inertial>
    <origin xyz="-0.00952234234158916 -0.0011699927569207014 -0.10340040159465233" rpy="0 0 0"/>
    <mass value="1.4601208347959271"/>
    <inertia ixx="0.008606" iyy="0.012386" izz="0.006685" ixy="0.000153" iyz="0.000102" ixz="0.000663"/>
  </inertial>
  <visual>
    <origin xyz="0.006681 0.141458 -0.0001" rpy="0 0 0"/>
    <geometry>
      <mesh filename="package://URDF_description/meshes/shell_Hr2w_Fork_v16_1.stl" scale="0.001 0.001 0.001"/>
    </geometry>
    <material name="silver"/>
  </visual>
  <collision>
    <origin xyz="0.006681 0.141458 -0.0001" rpy="0 0 0"/>
    <geometry>
      <mesh filename="package://URDF_description/meshes/shell_Hr2w_Fork_v16_1.stl" scale="0.001 0.001 0.001"/>
    </geometry>
  </collision>
</link>

<link name="shell_Femur_fork_v4_1">
  <inertial>
    <origin xyz="0.005503379988868675 0.012143529316580692 -0.1475952501799381" rpy="0 0 0"/>
    <mass value="1.5546715302452938"/>
    <inertia ixx="0.010066" iyy="0.011398" izz="0.004" ixy="4.8e-05" iyz="0.000518" ixz="-0.000163"/>
  </inertial>
  <visual>
    <origin xyz="0.000781 0.141458 0.21633" rpy="0 0 0"/>
    <geometry>
      <mesh filename="package://URDF_description/meshes/shell_Femur_fork_v4_1.stl" scale="0.001 0.001 0.001"/>
    </geometry>
    <material name="silver"/>
  </visual>
  <collision>
    <origin xyz="0.000781 0.141458 0.21633" rpy="0 0 0"/>
    <geometry>
      <mesh filename="package://URDF_description/meshes/shell_Femur_fork_v4_1.stl" scale="0.001 0.001 0.001"/>
    </geometry>
  </collision>
</link>

<link name="shell_Tibia_Alt_fork_v12_1">
  <inertial>
    <origin xyz="0.004915598034882956 -0.04719640915660481 -0.17927312154641073" rpy="0 0 0"/>
    <mass value="2.2859775944996787"/>
    <inertia ixx="0.044989" iyy="0.043477" izz="0.007379" ixy="-7.7e-05" iyz="-0.005175" ixz="-3.9e-05"/>
  </inertial>
  <visual>
    <origin xyz="0.000781 0.129933 0.41976" rpy="0 0 0"/>
    <geometry>
      <mesh filename="package://URDF_description/meshes/shell_Tibia_Alt_fork_v12_1.stl" scale="0.001 0.001 0.001"/>
    </geometry>
    <material name="silver"/>
  </visual>
  <collision>
    <origin xyz="0.000781 0.129933 0.41976" rpy="0 0 0"/>
    <geometry>
      <mesh filename="package://URDF_description/meshes/shell_Tibia_Alt_fork_v12_1.stl" scale="0.001 0.001 0.001"/>
    </geometry>
  </collision>
</link>

<link name="shell_Ap2r_v5_1">
  <inertial>
    <origin xyz="0.010749986836092951 0.048886118997542416 7.922562068607419e-07" rpy="0 0 0"/>
    <mass value="0.8540910374621573"/>
    <inertia ixx="0.001891" iyy="0.003306" izz="0.002482" ixy="-6e-06" iyz="-0.0" ixz="0.0"/>
  </inertial>
  <visual>
    <origin xyz="0.000781 0.185333 0.82986" rpy="0 0 0"/>
    <geometry>
      <mesh filename="package://URDF_description/meshes/shell_Ap2r_v5_1.stl" scale="0.001 0.001 0.001"/>
    </geometry>
    <material name="silver"/>
  </visual>
  <collision>
    <origin xyz="0.000781 0.185333 0.82986" rpy="0 0 0"/>
    <geometry>
      <mesh filename="package://URDF_description/meshes/shell_Ap2r_v5_1.stl" scale="0.001 0.001 0.001"/>
    </geometry>
  </collision>
</link>

<link name="shell_foot_v16_Mirror__1">
  <inertial>
    <origin xyz="0.009789939718177279 -0.004645323782557914 -0.04674675110597437" rpy="0 0 0"/>
    <mass value="0.8238828024731412"/>
    <inertia ixx="0.002022" iyy="0.003564" izz="0.003134" ixy="8.1e-05" iyz="-5.2e-05" ixz="-0.000704"/>
  </inertial>
  <visual>
    <origin xyz="-0.077029 0.141033 0.82986" rpy="0 0 0"/>
    <geometry>
      <mesh filename="package://URDF_description/meshes/shell_foot_v16_Mirror__1.stl" scale="0.001 0.001 0.001"/>
    </geometry>
    <material name="silver"/>
  </visual>
  <collision>
    <origin xyz="-0.077029 0.141033 0.82986" rpy="0 0 0"/>
    <geometry>
      <mesh filename="package://URDF_description/meshes/shell_foot_v16_Mirror__1.stl" scale="0.001 0.001 0.001"/>
    </geometry>
  </collision>
</link>

<link name="shell_Hp2r_Fork_v9_Mirror__1">
  <inertial>
    <origin xyz="-0.014198723177019458 0.048534344583808856 3.389556623735301e-05" rpy="0 0 0"/>
    <mass value="0.9668902038444638"/>
    <inertia ixx="0.002752" iyy="0.003388" izz="0.002866" ixy="3.4e-05" iyz="-1e-06" ixz="-0.0"/>
  </inertial>
  <visual>
    <origin xyz="0.0 -0.07805 -0.0" rpy="0 0 0"/>
    <geometry>
      <mesh filename="package://URDF_description/meshes/shell_Hp2r_Fork_v9_Mirror__1.stl" scale="0.001 0.001 0.001"/>
    </geometry>
    <material name="silver"/>
  </visual>
  <collision>
    <origin xyz="0.0 -0.07805 -0.0" rpy="0 0 0"/>
    <geometry>
      <mesh filename="package://URDF_description/meshes/shell_Hp2r_Fork_v9_Mirror__1.stl" scale="0.001 0.001 0.001"/>
    </geometry>
  </collision>
</link>

<link name="shell_Hr2w_Fork_v16_Mirror__1">
  <inertial>
    <origin xyz="-0.00952234234158919 0.0011699927569206459 -0.1034004015946524" rpy="0 0 0"/>
    <mass value="1.4601208347959274"/>
    <inertia ixx="0.008606" iyy="0.012386" izz="0.006685" ixy="-0.000153" iyz="-0.000102" ixz="0.000663"/>
  </inertial>
  <visual>
    <origin xyz="0.006681 -0.141458 -0.0001" rpy="0 0 0"/>
    <geometry>
      <mesh filename="package://URDF_description/meshes/shell_Hr2w_Fork_v16_Mirror__1.stl" scale="0.001 0.001 0.001"/>
    </geometry>
    <material name="silver"/>
  </visual>
  <collision>
    <origin xyz="0.006681 -0.141458 -0.0001" rpy="0 0 0"/>
    <geometry>
      <mesh filename="package://URDF_description/meshes/shell_Hr2w_Fork_v16_Mirror__1.stl" scale="0.001 0.001 0.001"/>
    </geometry>
  </collision>
</link>

<link name="shell_Femur_fork_v4_Mirror__1">
  <inertial>
    <origin xyz="0.00550338000288436 -0.012143529321659685 -0.14759525018361366" rpy="0 0 0"/>
    <mass value="1.5546715299014076"/>
    <inertia ixx="0.010066" iyy="0.011398" izz="0.004" ixy="-4.8e-05" iyz="-0.000518" ixz="-0.000163"/>
  </inertial>
  <visual>
    <origin xyz="0.000781 -0.141458 0.21633" rpy="0 0 0"/>
    <geometry>
      <mesh filename="package://URDF_description/meshes/shell_Femur_fork_v4_Mirror__1.stl" scale="0.001 0.001 0.001"/>
    </geometry>
    <material name="silver"/>
  </visual>
  <collision>
    <origin xyz="0.000781 -0.141458 0.21633" rpy="0 0 0"/>
    <geometry>
      <mesh filename="package://URDF_description/meshes/shell_Femur_fork_v4_Mirror__1.stl" scale="0.001 0.001 0.001"/>
    </geometry>
  </collision>
</link>

<link name="shell_Tibia_Alt_fork_v12_Mirror__1">
  <inertial>
    <origin xyz="0.0049155980293715575 0.0471964080103576 -0.17927312303319642" rpy="0 0 0"/>
    <mass value="2.285977814754967"/>
    <inertia ixx="0.044989" iyy="0.043477" izz="0.007379" ixy="7.7e-05" iyz="0.005175" ixz="-3.9e-05"/>
  </inertial>
  <visual>
    <origin xyz="0.000781 -0.129933 0.41976" rpy="0 0 0"/>
    <geometry>
      <mesh filename="package://URDF_description/meshes/shell_Tibia_Alt_fork_v12_Mirror__1.stl" scale="0.001 0.001 0.001"/>
    </geometry>
    <material name="silver"/>
  </visual>
  <collision>
    <origin xyz="0.000781 -0.129933 0.41976" rpy="0 0 0"/>
    <geometry>
      <mesh filename="package://URDF_description/meshes/shell_Tibia_Alt_fork_v12_Mirror__1.stl" scale="0.001 0.001 0.001"/>
    </geometry>
  </collision>
</link>

<link name="shell_Ap2r_v5_Mirror__1">
  <inertial>
    <origin xyz="0.01074998683609302 -0.048886118997542305 7.922562069717642e-07" rpy="0 0 0"/>
    <mass value="0.8540910374621569"/>
    <inertia ixx="0.001891" iyy="0.003306" izz="0.002482" ixy="6e-06" iyz="0.0" ixz="0.0"/>
  </inertial>
  <visual>
    <origin xyz="0.000781 -0.185333 0.82986" rpy="0 0 0"/>
    <geometry>
      <mesh filename="package://URDF_description/meshes/shell_Ap2r_v5_Mirror__1.stl" scale="0.001 0.001 0.001"/>
    </geometry>
    <material name="silver"/>
  </visual>
  <collision>
    <origin xyz="0.000781 -0.185333 0.82986" rpy="0 0 0"/>
    <geometry>
      <mesh filename="package://URDF_description/meshes/shell_Ap2r_v5_Mirror__1.stl" scale="0.001 0.001 0.001"/>
    </geometry>
  </collision>
</link>

<link name="shell_foot_v16_1">
  <inertial>
    <origin xyz="0.011789939718177475 0.004645323782557942 -0.04674675110597404" rpy="0 0 0"/>
    <mass value="0.8238828024731404"/>
    <inertia ixx="0.002022" iyy="0.003564" izz="0.003134" ixy="-8.1e-05" iyz="5.2e-05" ixz="-0.000704"/>
  </inertial>
  <visual>
    <origin xyz="-0.077029 -0.141033 0.82986" rpy="0 0 0"/>
    <geometry>
      <mesh filename="package://URDF_description/meshes/shell_foot_v16_1.stl" scale="0.001 0.001 0.001"/>
    </geometry>
    <material name="silver"/>
  </visual>
  <collision>
    <origin xyz="-0.077029 -0.141033 0.82986" rpy="0 0 0"/>
    <geometry>
      <mesh filename="package://URDF_description/meshes/shell_foot_v16_1.stl" scale="0.001 0.001 0.001"/>
    </geometry>
  </collision>
</link>

<joint name="Revolute 2" type="revolute">
  <origin xyz="-0.032 -0.1279 0.3292" rpy="0 0 0"/>
  <parent link="shell_torso_1"/>
  <child link="shell_Sp2rR_fork_v6_1"/>
  <axis xyz="0.0 1.0 0.0"/>
  <limit upper="1.570796" lower="-3.141593" effort="100" velocity="100"/>
</joint>

<joint name="Revolute 3" type="revolute">
  <origin xyz="0.00102 -0.08839 0.0" rpy="0 0 0"/>
  <parent link="shell_Sp2rR_fork_v6_1"/>
  <child link="shell_Sr2wR_fork_v14_1"/>
  <axis xyz="1.0 0.0 0.0"/>
  <limit upper="0.174533" lower="-2.268928" effort="100" velocity="100"/>
</joint>

<joint name="Revolute 4" type="revolute">
  <origin xyz="-0.00105 0.0 -0.146483" rpy="0 0 0"/>
  <parent link="shell_Sr2wR_fork_v14_1"/>
  <child link="shell_Humerus_Fork_v8_1"/>
  <axis xyz="0.0 0.0 1.0"/>
  <limit upper="1.570796" lower="-1.570796" effort="100" velocity="100"/>
</joint>

<joint name="Revolute 5" type="revolute">
  <origin xyz="0.0 0.00077 -0.15139" rpy="0 0 0"/>
  <parent link="shell_Humerus_Fork_v8_1"/>
  <child link="shell_Ulna_Fork_v5_1"/>
  <axis xyz="0.0 1.0 0.0"/>
  <limit upper="0.0" lower="-2.268928" effort="100" velocity="100"/>
</joint>

<joint name="Revolute 6" type="revolute">
  <origin xyz="0.0 -0.00095 -0.100482" rpy="0 0 0"/>
  <parent link="shell_Ulna_Fork_v5_1"/>
  <child link="shell_Radius_gen2_v31_1"/>
  <axis xyz="0.0 0.0 1.0"/>
  <limit upper="0.0" lower="-3.141593" effort="100" velocity="100"/>
</joint>

<joint name="Revolute 7" type="revolute">
  <origin xyz="-0.032 0.1279 0.3292" rpy="0 0 0"/>
  <parent link="shell_torso_1"/>
  <child link="shell_Sp2rR_fork_v6_Mirror__1"/>
  <axis xyz="0.0 1.0 0.0"/>
  <limit upper="1.570796" lower="-3.141593" effort="100" velocity="100"/>
</joint>

<joint name="Revolute 8" type="revolute">
  <origin xyz="0.00102 0.08839 0.0" rpy="0 0 0"/>
  <parent link="shell_Sp2rR_fork_v6_Mirror__1"/>
  <child link="shell_Sr2wR_fork_v14_Mirror__1"/>
  <axis xyz="1.0 0.0 0.0"/>
  <limit upper="2.268928" lower="-0.174533" effort="100" velocity="100"/>
</joint>

<joint name="Revolute 9" type="revolute">
  <origin xyz="-0.00105 0.0 -0.146483" rpy="0 0 0"/>
  <parent link="shell_Sr2wR_fork_v14_Mirror__1"/>
  <child link="shell_Humerus_Fork_v8_Mirror__1"/>
  <axis xyz="0.0 0.0 1.0"/>
  <limit upper="1.570796" lower="-1.570796" effort="100" velocity="100"/>
</joint>

<joint name="Revolute 10" type="revolute">
  <origin xyz="0.0 -0.00077 -0.15139" rpy="0 0 0"/>
  <parent link="shell_Humerus_Fork_v8_Mirror__1"/>
  <child link="shell_Ulna_Fork_v5_Mirror__1"/>
  <axis xyz="0.0 1.0 0.0"/>
  <limit upper="0.0" lower="-2.268928" effort="100" velocity="100"/>
</joint>

<joint name="Revolute 11" type="revolute">
  <origin xyz="0.0 0.00095 -0.100482" rpy="0 0 0"/>
  <parent link="shell_Ulna_Fork_v5_Mirror__1"/>
  <child link="shell_Radius_gen2_v31_Mirror__1"/>
  <axis xyz="0.0 0.0 1.0"/>
  <limit upper="3.141593" lower="0.0" effort="100" velocity="100"/>
</joint>

<joint name="Revolute 14" type="revolute">
  <origin xyz="0.0 0.0 0.0" rpy="0 0 0"/>
  <parent link="scaphoid_1"/>
  <child link="hand_secondIter_v9_Mirror__1"/>
  <axis xyz="1.0 0.0 0.0"/>
  <limit upper="0.349066" lower="-0.698132" effort="100" velocity="100"/>
</joint>

<joint name="Revolute 17" type="revolute">
  <origin xyz="0.0 0.0 0.0" rpy="0 0 0"/>
  <parent link="scaphoid_Mirror__1"/>
  <child link="hand_secondIter_v9_1"/>
  <axis xyz="1.0 0.0 0.0"/>
  <limit upper="0.698132" lower="-0.349066" effort="100" velocity="100"/>
</joint>

<joint name="Revolute 20" type="revolute">
  <origin xyz="0.0 0.0 0.08448" rpy="0 0 0"/>
  <parent link="base_link"/>
  <child link="shell_Fr2w_Fork_v6_1"/>
  <axis xyz="0.0 0.0 1.0"/>
  <limit upper="1.570796" lower="-1.570796" effort="100" velocity="100"/>
</joint>

<joint name="Revolute 21" type="revolute">
  <origin xyz="0.0305 0.0 0.1522" rpy="0 0 0"/>
  <parent link="shell_Fr2w_Fork_v6_1"/>
  <child link="shell_Fp2r_Fork_dual_v3_1"/>
  <axis xyz="1.0 0.0 0.0"/>
  <limit upper="0.628319" lower="-0.628319" effort="100" velocity="100"/>
</joint>

<joint name="Revolute 22" type="revolute">
  <origin xyz="0.000874 -0.0 0.0" rpy="0 0 0"/>
  <parent link="shell_Fp2r_Fork_dual_v3_1"/>
  <child link="shell_torso_1"/>
  <axis xyz="0.0 1.0 0.0"/>
  <limit upper="0.907571" lower="-0.287979" effort="100" velocity="100"/>
</joint>

<joint name="Revolute 23" type="revolute">
  <origin xyz="6.5e-05 0.0 -0.207787" rpy="0 0 0"/>
  <parent link="shell_Radius_gen2_v31_1"/>
  <child link="scaphoid_1"/>
  <axis xyz="0.0 1.0 0.0"/>
  <limit upper="0.523599" lower="-0.523599" effort="100" velocity="100"/>
</joint>

<joint name="Revolute 24" type="revolute">
  <origin xyz="6.5e-05 0.0 -0.206787" rpy="0 0 0"/>
  <parent link="shell_Radius_gen2_v31_Mirror__1"/>
  <child link="scaphoid_Mirror__1"/>
  <axis xyz="0.0 1.0 0.0"/>
  <limit upper="0.523599" lower="-0.523599" effort="100" velocity="100"/>
</joint>

<joint name="Revolute 25" type="revolute">
  <origin xyz="0.0 -0.07805 0.0" rpy="0 0 0"/>
  <parent link="base_link"/>
  <child link="shell_Hp2r_Fork_v9_1"/>
  <axis xyz="0.0 1.0 0.0"/>
  <limit upper="1.570796" lower="-1.570796" effort="100" velocity="100"/>
</joint>

<joint name="Revolute 26" type="revolute">
  <origin xyz="-0.006681 -0.063408 0.0001" rpy="0 0 0"/>
  <parent link="shell_Hp2r_Fork_v9_1"/>
  <child link="shell_Hr2w_Fork_v16_1"/>
  <axis xyz="1.0 0.0 0.0"/>
  <limit upper="0.610865" lower="-1.570796" effort="100" velocity="100"/>
</joint>

<joint name="Revolute 27" type="revolute">
  <origin xyz="0.0059 0.0 -0.21643" rpy="0 0 0"/>
  <parent link="shell_Hr2w_Fork_v16_1"/>
  <child link="shell_Femur_fork_v4_1"/>
  <axis xyz="0.0 0.0 1.0"/>
  <limit upper="1.570796" lower="-1.570796" effort="100" velocity="100"/>
</joint>

<joint name="Revolute 28" type="revolute">
  <origin xyz="0.0 0.011525 -0.20343" rpy="0 0 0"/>
  <parent link="shell_Femur_fork_v4_1"/>
  <child link="shell_Tibia_Alt_fork_v12_1"/>
  <axis xyz="0.0 1.0 0.0"/>
  <limit upper="2.617994" lower="0.0" effort="100" velocity="100"/>
</joint>

<joint name="Revolute 29" type="revolute">
  <origin xyz="0.0 -0.0554 -0.4101" rpy="0 0 0"/>
  <parent link="shell_Tibia_Alt_fork_v12_1"/>
  <child link="shell_Ap2r_v5_1"/>
  <axis xyz="0.0 1.0 0.0"/>
  <limit upper="0.785398" lower="-0.785398" effort="100" velocity="100"/>
</joint>

<joint name="Revolute 30" type="revolute">
  <origin xyz="0.07781 0.0443 0.0" rpy="0 0 0"/>
  <parent link="shell_Ap2r_v5_1"/>
  <child link="shell_foot_v16_Mirror__1"/>
  <axis xyz="1.0 0.0 0.0"/>
  <limit upper="0.785398" lower="0.0" effort="100" velocity="100"/>
</joint>

<joint name="Revolute 31" type="revolute">
  <origin xyz="0.0 0.07805 0.0" rpy="0 0 0"/>
  <parent link="base_link"/>
  <child link="shell_Hp2r_Fork_v9_Mirror__1"/>
  <axis xyz="0.0 1.0 0.0"/>
  <limit upper="1.570796" lower="-1.570796" effort="100" velocity="100"/>
</joint>

<joint name="Revolute 32" type="revolute">
  <origin xyz="-0.006681 0.063408 0.0001" rpy="0 0 0"/>
  <parent link="shell_Hp2r_Fork_v9_Mirror__1"/>
  <child link="shell_Hr2w_Fork_v16_Mirror__1"/>
  <axis xyz="1.0 0.0 0.0"/>
  <limit upper="1.570796" lower="-0.610865" effort="100" velocity="100"/>
</joint>

<joint name="Revolute 33" type="revolute">
  <origin xyz="0.0059 0.0 -0.21643" rpy="0 0 0"/>
  <parent link="shell_Hr2w_Fork_v16_Mirror__1"/>
  <child link="shell_Femur_fork_v4_Mirror__1"/>
  <axis xyz="0.0 0.0 1.0"/>
  <limit upper="1.570796" lower="-1.570796" effort="100" velocity="100"/>
</joint>

<joint name="Revolute 34" type="revolute">
  <origin xyz="0.0 -0.011525 -0.20343" rpy="0 0 0"/>
  <parent link="shell_Femur_fork_v4_Mirror__1"/>
  <child link="shell_Tibia_Alt_fork_v12_Mirror__1"/>
  <axis xyz="0.0 1.0 0.0"/>
  <limit upper="2.617994" lower="0.0" effort="100" velocity="100"/>
</joint>

<joint name="Revolute 35" type="revolute">
  <origin xyz="0.0 0.0554 -0.4101" rpy="0 0 0"/>
  <parent link="shell_Tibia_Alt_fork_v12_Mirror__1"/>
  <child link="shell_Ap2r_v5_Mirror__1"/>
  <axis xyz="0.0 1.0 0.0"/>
  <limit upper="0.785398" lower="-0.785398" effort="100" velocity="100"/>
</joint>

<joint name="Revolute 36" type="revolute">
  <origin xyz="0.07781 -0.0443 0.0" rpy="0 0 0"/>
  <parent link="shell_Ap2r_v5_Mirror__1"/>
  <child link="shell_foot_v16_1"/>
  <axis xyz="1.0 0.0 0.0"/>
  <limit upper="0.0" lower="-0.785398" effort="100" velocity="100"/>
</joint>

</robot>
